Workbook

Sheet Cover
A1: ERR Quantification Spreadsheet
A2: Verra VCS · VM0042 v2.2 (Improved Agricultural Land Management) · prepared for VVB validation/verification
B4: 1 · Project identification
B5: Project title | C5: «enter»
B6: VCS project ID | C6: «enter»
B7: Project proponent | C7: CarboNature
B8: Country / region | C8: «enter»
B9: Crop(s) — open field | C9: «enter»
B10: Methodology | C10: VM0042 v2.2 (Improved Agricultural Land Management)
B11: Module | C11: VMD0053 (Model Calibration, Validation & Uncertainty) | D11: Applicable when SOC / soil N₂O use QA1.
B12: Crediting period | C12: «enter»
B13: Monitoring / reporting period | C13: «enter»
B14: Prepared by | C14: «enter»
B15: Date | C15: «enter»
B16: Spreadsheet version | C16: v1.0
B18: 2 · GHG accounting basis
B19: GWP source | C19: IPCC AR5 (2013): N₂O = 265, CH₄ = 28 | D19: Mandated by VM0042 v2.2. Editable in "Fixed Parameters".
B20: Emission factors | C20: IPCC 2019 Refinement (default factors, QA3) | D20: EF_N_direct, Frac_GASF/GASM, Frac_LEACH, etc. — see "Fixed Parameters" + "Index".
B21: Conservativeness | C21: EF_N_direct 0.013↓ / 0.019↑ per project N trend (§8.3)
B23: 3 · Quantification approach map (per pool/source) — §8.1
B24: Pool / source | C24: Approach | D24: Computed in
B25: SOC stock change (removals) | C25: ="QA3/QA1 selector → "&'Fixed Parameters'!$B$7 -> QA3/QA1 selector → QA3 | D25: SOC Removals (QA1)
B26: Soil N₂O (fertilizer + N-fixing) | C26: ={selector} | D26: Baseline Emissions / SOC Removals (QA1)
B27: Fossil-fuel CO₂ | C27: QA3 — Default factors | D27: Baseline Emissions / Project Emissions
B28: Residue-burning N₂O | C28: QA3 — Default factors | D28: Baseline Emissions / Project Emissions
B29: Each source uses the SAME approach in baseline and project; strata on different approaches are accounted separately (no double-counting).
B31: 4 · ERR traceability map (equation → sheet)
B32: Quantity | C32: VM0042 eq. | D32: Sheet | E32: Column
B33: CO₂ from fossil fuel | C33: 6, 7 | D33: Baseline Emissions / Project Emissions | E33: K
B34: N₂O direct (fertilizer N) | C34: 18, 19, 20 | D34: Baseline Emissions / Project Emissions | E34: F (FSN/FON in D,E)
B35: N₂O indirect (volat. + leach.) | C35: 21, 22, 23 | D35: Baseline Emissions / Project Emissions | E35: G, H, I
B36: N₂O from N-fixing residue | C36: 24, 25 | D36: Baseline Emissions / Project Emissions | E36: M
B37: N₂O from residue burning | C37: 32 | D37: Baseline Emissions / Project Emissions | E37: L
B38: Net reductions (baseline − project) | C38: 37, 38 | D38: Net Reductions | E38: H
B39: SOC removals | C39: 4, 5, 40, 41 | D39: SOC Removals (QA1) | E39: I
B40: Estimated VCUs | C40: — | D40: Project Summary (VVB) | E40: —
B42: 5 · Companion documents (VVB package)
B43: Model Validation Report (MVR) | C43: Proponent-authored, per VMD0053 | D43: Required under QA1. See MVR template/skeleton.
B44: IME Assessment Report | C44: Authored by the IME hired by the VVB | D44: Confirms model applicability, calibration, prediction error.
B45: ESM worksheet (SOC) | C45: Wendt & Hauser 2013 (Verra) | D45: Equivalent Soil Mass for SOC stock comparison (QA1/QA2).
...

Sheet README
A1: CarboNature — GHG Calculator
A2: VM0042 v2.2 · Improved Agricultural Land Management · Open-Field crops · Quantification Approach 3 (Default Factors)
B4: Purpose | C4: Computes baseline and project GHG emissions from nitrogen fertilizers and fossil fuel, per quantification unit (farm/plot) per year, for multi-year monitoring under Verra VM0042 v2.2. Output is VVB-audit ready.
B5: Methodology | C5: VM0042 v2.2 (Improved ALM). Emission factors per the 2019 Refinement to the 2006 IPCC Guidelines, Vol.4 Ch.11 (N2O) & Ch.2/Vol.2 Ch.3 (fuel, burning). GWP per IPCC AR5 (2013).
B6: Scope (Phase 1) | C6: Open-field crops only (NOT orchards/groves/forests). Sources: CO2 from fossil-fuel combustion; direct & indirect N2O from synthetic + organic N fertilizers; N2O from N-fixing crop residues; N2O from agricultural-residue burning.
B7: Out of scope (Phase 2) | C7: Leakage (activity-shifting / market / ecological); SOC modeling; liming & urea CO2; rice CH4; manure-deposition N2O from grazing. Placeholders are included where relevant.
B8: Baseline rule | C8: Baseline = average of the 3 years preceding the project start date (enter the 3 years per farm in "Baseline Inputs").
B10: How to read the colours
C11: INPUT (yellow) — enter your activity data here (invoices, declarations, machinery, etc.)
C12: CALCULATED (grey) — live formula, do not overwrite
C13: FIXED PARAMETER (blue) — emission factors & constants, defaulted to VM0042 v2.2 / IPCC 2019. Editable only with documented justification.
C14: REMOVALS / QA1 (purple) — soil-carbon (SOC) measure-&-model inputs for the hybrid model.
B16: Sheet guide
B17: Index | C17: Every variable & parameter: symbol, unit, equation, description, source.
B18: Equations | C18: Every VM0042 v2.2 equation used, written out with plain explanation.
B19: Fixed Parameters | C19: Emission factors, GWP, fractions — with climate-zone & conservativeness logic.
B20: Fertilizer Library | C20: Common fertilizers & their N content (auto-looked-up by name).
B21: Machinery-Diesel | C21: Convert machinery HP × hours/ha × area → diesel litres (feeds fuel input).
B22: Baseline / Project Inputs | C22: Activity data per farm-year (fertilizers, fuel, residues, N-fixing).
B23: Baseline / Project Emissions | C23: Per-row computed emissions (live formulas).
B24: Net Reductions | C24: Baseline − Project per source = emission reductions (+ leakage placeholder).
B25: Project Summary (VVB) | C25: Roll-up across all farms — the sheet to hand to the VVB.

Sheet Fixed Parameters
A1: Fixed Parameters
A2: Defaults per VM0042 v2.2 & IPCC 2019 Refinement. Editable — change only with documented justification.
A3: Parameter | B3: Value | C3: Unit | D3: Eq. | E3: Source / Note
A4: Climate zone | B4: wet | E4: wet = precip/PET > 1 (or tropical >1000 mm/yr); else dry. Drives EF_N_direct & Frac_LEACH.
A5: Dry-climate irrigation? | B5: no | E5: Only used when climate = dry. "yes" (non-drip irrigation) keeps Frac_LEACH = 0.24.
A6: Project N trend vs baseline | B6: decrease | E6: Conservativeness rule (VM0042 §8.3): decrease→EF_N_direct 0.013 (low); increase→0.019 (high); flat→0.016.
A7: Soil N2O approach | B7: QA3 | E7: QA3 = default EF (computed on the emissions sheets). QA1 = soil N2O is MODELED in the "SOC Removals (QA1)" sheet; the QA3 N2O is then shown for reference but EXCLUDED from totals to prevent double-counting (§8.1). Fuel CO2 stays QA3 either way.
A9: EF_CO2_diesel | B9: 0.002886 | C9: t CO2e/L | D9: 7 | E9: VM0042 v2.2; IPCC 2019 Vol.2 Ch.3 Table 3.3.1
A10: EF_CO2_gasoline | B10: 0.00281 | C10: t CO2e/L | D10: 7 | E10: VM0042 v2.2; IPCC 2019 Vol.2 Ch.3 Table 3.3.1
A11: GWP_N2O | B11: 265 | C11: t CO2e/t N2O | D11: 18,22-24 | E11: IPCC AR5 (2013), mandated by VM0042 v2.2. Override to 273 only if VCS Standard adopts AR6.
A12: EF_N_direct_wet | B12: 0.016 | C12: t N2O-N/t N | D12: 18,24 | E12: IPCC 2019 Table 11.1 (synthetic, wet). Range 0.013-0.019.
A13: EF_N_direct_dry | B13: 0.005 | C13: t N2O-N/t N | D13: 18,24 | E13: IPCC 2019 Table 11.1 (all N, dry). Range 0.000-0.011.
A14: EF_N_direct_low | B14: 0.013 | C14: t N2O-N/t N | D14: 18,24 | E14: Conservative low end (wet) — used when project N decreases.
A15: EF_N_direct_high | B15: 0.019 | C15: t N2O-N/t N | D15: 18,24 | E15: Conservative high end (wet) — used when project N increases.
A16: EF_N_direct (applied) | B16: =IF('Fixed Parameters'!$B$4="dry",'Fixed Parameters'!$B$13,IF('Fixed Parameters'!$B$6="decrease",'Fixed Parameters'!$B$14,IF('Fixed Parameters'!$B$6="increase",'Fixed Parameters'!$B$15,'Fixed Parameters'!$B$12))) -> 0.013 | C16: t N2O-N/t N | D16: 18,24 | E16: Auto-selected from climate zone + conservativeness direction above. This is the value the engine uses.
A17: Frac_GASF | B17: 0.11 | C17: dimensionless | D17: 22 | E17: IPCC 2019 Table 11.3 (synthetic N volatilised, aggregated).
A18: Frac_GASM | B18: 0.21 | C18: dimensionless | D18: 22 | E18: IPCC 2019 Table 11.3 (organic N volatilised).
A19: EF_N_volat | B19: 0.014 | C19: t N2O-N/t N | D19: 22 | E19: IPCC 2019 Table 11.3 (EF4, atmospheric deposition).
A20: Frac_LEACH_wet | B20: 0.24 | C20: dimensionless | D20: 23 | E20: IPCC 2019 Table 11.3 (wet, or dry+non-drip irrigation).
A21: Frac_LEACH (applied) | B21: =IF(OR('Fixed Parameters'!$B$4="wet",AND('Fixed Parameters'!$B$4="dry",'Fixed Parameters'!$B$5="yes")),'Fixed Parameters'!$B$20,0) -> 0.24 | C21: dimensionless | D21: 23 | E21: Auto: 0.24 for wet / dry-irrigated; 0 otherwise.
A22: EF_N_leach | B22: 0.011 | C22: t N2O-N/t N | D22: 23 | E22: IPCC 2019 Table 11.3 (EF5, leaching/runoff).
A23: Cf_combustion | B23: 0.5 | C23: fraction | D23: 32 | E23: IPCC 2019 Vol.4 Table 2.6 (combustion factor). Verify per crop.
A24: EF_c_N2O | B24: 0.07 | C24: g N2O/kg d.m. | D24: 32 | E24: IPCC 2019 Vol.4 Table 2.5 (N2O from residue burning).
A25: N2O_N_to_N2O | B25: =44/28 -> 1.5714286 | C25: ratio | D25: all | E25: Molar mass N2O / N2 (converts N2O-N to N2O).

Sheet Fertilizer Library
A1: Fertilizer Library
A2: N content auto-looked-up by exact name from the Inputs sheets. Add rows for any fertilizer you use.
A3: Fertilizer name | B3: N content (t N/t) | C3: Class | D3: Density (t/m³) | E3: Note
A4: Urea 46-0-0 | B4: 0.46 | C4: synthetic-urea | E4: Solid urea
A5: UAN / Uran 32-0-0 | B5: 0.32 | C5: synthetic-urea | E5: Liquid urea-ammonium-nitrate
A6: Ammonium nitrate 34-0-0 | B6: 0.34 | C6: synthetic-other
A7: Ammonium sulphate 21-0-0 | B7: 0.21 | C7: synthetic-other
A8: Ammonium nitrate solution 21% | B8: 0.21 | C8: synthetic-other
A9: Ammonium nitrate sulphur sol. 12% | B9: 0.12 | C9: synthetic-other
A10: N-P-K 8-0-8 | B10: 0.08 | C10: synthetic-other | E10: Potassium-rich blend
A11: N-P-K 9-0-9 | B11: 0.09 | C11: synthetic-other
A12: N-P-K 12-1-6 | B12: 0.12 | C12: synthetic-other
A13: N-P-K 15-15-15 | B13: 0.15 | C13: synthetic-other
A14: N-P-K 20-20-20 | B14: 0.2 | C14: synthetic-other
A15: MAP 11-52-0 | B15: 0.11 | C15: synthetic-other
A16: DAP 18-46-0 | B16: 0.18 | C16: synthetic-other
A17: Potassium nitrate 13-0-46 | B17: 0.13 | C17: synthetic-other
A18: Calcium nitrate 15.5-0-0 | B18: 0.155 | C18: synthetic-other
A19: Compost (generic) | B19: 0.015 | C19: organic | D19: 0.6 | E19: N ~1-2.5% d.m.; confirm by lab. m³×density = tonnes.
A20: Manure (cattle, solid) | B20: 0.006 | C20: organic | D20: 0.8 | E20: Confirm N by analysis.
A21: Manure (poultry) | B21: 0.03 | C21: organic | D21: 0.7 | E21: Confirm N by analysis.

Sheet Machinery-Diesel
A1: Machinery → Diesel
A2: Estimate diesel litres from machinery when fuel invoices are unavailable. Litre total can be pasted into the fuel column of an Inputs row.
A3: Formula: Diesel (L) = Rated power (kW) × Load factor × SFC (L/kWh) × Hours per ha × Area (ha). Rated kW = HP × 0.7457. Default SFC ≈ 0.27 L/kWh (IPCC 2019 / EPA NONROAD diesel).
A4: Equipment | B4: Rated HP | C4: Rated kW | D4: Load factor | E4: SFC (L/kWh) | F4: Hours/ha | G4: Area (ha) | H4: Diesel (L)
A5: Tractor (heavy, ploughing) | B5: 120 | C5: =IF(B5="","",B5*0.7457) -> 89.484 | D5: 0.55 | E5: 0.27 | F5: 6 | G5: 50 | H5: =IF(C5="","",C5*D5*E5*F5*G5) -> 3986.5122
A6: Tractor (medium, spraying) | B6: 80 | C6: =IF(B6="","",B6*0.7457) -> 59.656 | D6: 0.45 | E6: 0.27 | F6: 3 | G6: 50 | H6: =IF(C6="","",C6*D6*E6*F6*G6) -> 1087.2306
A7: Combine harvester | B7: 250 | C7: =IF(B7="","",B7*0.7457) -> 186.425 | D7: 0.6 | E7: 0.27 | F7: 1.5 | G7: 50 | H7: =IF(C7="","",C7*D7*E7*F7*G7) -> 2265.0638
C8: =IF(B8="","",B8*0.7457) | H8: =IF(C8="","",C8*D8*E8*F8*G8)
G9: TOTAL diesel (L): | H9: =SUM(H5:H8) -> 7338.8066

Sheet Baseline Inputs
A1: Baseline Inputs
A2: Activity data for the 3 years preceding project start (one row per farm-year). Yellow = enter data; grey = auto.
A4: Farm / unit | B4: Year | C4: Area (ha) | D4: Organic fert | H4: Synthetic fert 1 | K4: Synthetic fert 2 | N4: Synthetic fert 3 | Q4: Fuel | S4: Residue burnt (kg) | T4: N-fixing crop residue
D5: Name | E5: Mass (t) | F5: N (t N/t) | G5: Interval (yr) | H5: Name | I5: Mass (t) | J5: N (t N/t) | K5: Name | L5: Mass (t) | M5: N (t N/t) | N5: Name | O5: Mass (t) | P5: N (t N/t) | Q5: Diesel (L) | R5: Gasoline (L) | T5: Dry matter (t) | U5: N (t N/t d.m.)
A6: Farm_A | B6: 2022 | C6: 50 | D6: Compost (generic) | E6: 500 | F6: =IFERROR(VLOOKUP(D6,'Fertilizer Library'!$A:$B,2,FALSE),"") -> 0.015 | G6: 10 | H6: UAN / Uran 32-0-0 | I6: 40 | J6: =IFERROR(VLOOKUP(H6,'Fertilizer Library'!$A:$B,2,FALSE),"") -> 0.32 | K6: N-P-K 8-0-8 | L6: 25 | M6: =IFERROR(VLOOKUP(K6,'Fertilizer Library'!$A:$B,2,FALSE),"") -> 0.08 | P6: =IFERROR(VLOOKUP(N6,'Fertilizer Library'!$A:$B,2,FALSE),"") | Q6: 9000 | S6: 0 | T6: 0
A7: Farm_A | B7: 2023 | C7: 50 | E7: 0 | F7: =IFERROR(VLOOKUP(D7,'Fertilizer Library'!$A:$B,2,FALSE),"") | G7: 10 | H7: UAN / Uran 32-0-0 | I7: 42 | J7: =IFERROR(VLOOKUP(H7,'Fertilizer Library'!$A:$B,2,FALSE),"") -> 0.32 | K7: N-P-K 8-0-8 | L7: 28 | M7: =IFERROR(VLOOKUP(K7,'Fertilizer Library'!$A:$B,2,FALSE),"") -> 0.08 | P7: =IFERROR(VLOOKUP(N7,'Fertilizer Library'!$A:$B,2,FALSE),"") | Q7: 9200 | S7: 0 | T7: 0
A8: Farm_A | B8: 2024 | C8: 50 | E8: 0 | F8: =IFERROR(VLOOKUP(D8,'Fertilizer Library'!$A:$B,2,FALSE),"") | G8: 10 | H8: UAN / Uran 32-0-0 | I8: 38 | J8: =IFERROR(VLOOKUP(H8,'Fertilizer Library'!$A:$B,2,FALSE),"") -> 0.32 | K8: N-P-K 9-0-9 | L8: 22 | M8: =IFERROR(VLOOKUP(K8,'Fertilizer Library'!$A:$B,2,FALSE),"") -> 0.09 | P8: =IFERROR(VLOOKUP(N8,'Fertilizer Library'!$A:$B,2,FALSE),"") | Q8: 8800 | S8: 0 | T8: 0
A9: Farm_B | B9: 2022 | C9: 30 | D9: Manure (cattle, solid) | E9: 120 | F9: =IFERROR(VLOOKUP(D9,'Fertilizer Library'!$A:$B,2,FALSE),"") -> 0.006 | G9: 1 | H9: Ammonium sulphate 21-0-0 | I9: 30 | J9: =IFERROR(VLOOKUP(H9,'Fertilizer Library'!$A:$B,2,FALSE),"") -> 0.21 | M9: =IFERROR(VLOOKUP(K9,'Fertilizer Library'!$A:$B,2,FALSE),"") | P9: =IFERROR(VLOOKUP(N9,'Fertilizer Library'!$A:$B,2,FALSE),"") | Q9: 5400 | S9: 1500 | T9: 2 | U9: 0.02
A10: Farm_B | B10: 2023 | C10: 30 | D10: Manure (cattle, solid) | E10: 110 | F10: =IFERROR(VLOOKUP(D10,'Fertilizer Library'!$A:$B,2,FALSE),"") -> 0.006 | G10: 1 | H10: Ammonium sulphate 21-0-0 | I10: 32 | J10: =IFERROR(VLOOKUP(H10,'Fertilizer Library'!$A:$B,2,FALSE),"") -> 0.21 | M10: =IFERROR(VLOOKUP(K10,'Fertilizer Library'!$A:$B,2,FALSE),"") | P10: =IFERROR(VLOOKUP(N10,'Fertilizer Library'!$A:$B,2,FALSE),"") | Q10: 5600 | S10: 1400 | T10: 2.2 | U10: 0.02
A11: Farm_B | B11: 2024 | C11: 30 | D11: Manure (cattle, solid) | E11: 130 | F11: =IFERROR(VLOOKUP(D11,'Fertilizer Library'!$A:$B,2,FALSE),"") -> 0.006 | G11: 1 | H11: Ammonium sulphate 21-0-0 | I11: 28 | J11: =IFERROR(VLOOKUP(H11,'Fertilizer Library'!$A:$B,2,FALSE),"") -> 0.21 | M11: =IFERROR(VLOOKUP(K11,'Fertilizer Library'!$A:$B,2,FALSE),"") | P11: =IFERROR(VLOOKUP(N11,'Fertilizer Library'!$A:$B,2,FALSE),"") | Q11: 5200 | S11: 1600 | T11: 1.8 | U11: 0.02
F12: =IFERROR(VLOOKUP(D12,'Fertilizer Library'!$A:$B,2,FALSE),"") | J12: =IFERROR(VLOOKUP(H12,'Fertilizer Library'!$A:$B,2,FALSE),"") | M12: =IFERROR(VLOOKUP(K12,'Fertilizer Library'!$A:$B,2,FALSE),"") | P12: =IFERROR(VLOOKUP(N12,'Fertilizer Library'!$A:$B,2,FALSE),"")
F13: =IFERROR(VLOOKUP(D13,'Fertilizer Library'!$A:$B,2,FALSE),"") | J13: =IFERROR(VLOOKUP(H13,'Fertilizer Library'!$A:$B,2,FALSE),"") | M13: =IFERROR(VLOOKUP(K13,'Fertilizer Library'!$A:$B,2,FALSE),"") | P13: =IFERROR(VLOOKUP(N13,'Fertilizer Library'!$A:$B,2,FALSE),"")
F14: =IFERROR(VLOOKUP(D14,'Fertilizer Library'!$A:$B,2,FALSE),"") | J14: =IFERROR(VLOOKUP(H14,'Fertilizer Library'!$A:$B,2,FALSE),"") | M14: =IFERROR(VLOOKUP(K14,'Fertilizer Library'!$A:$B,2,FALSE),"") | P14: =IFERROR(VLOOKUP(N14,'Fertilizer Library'!$A:$B,2,FALSE),"")
F15: =IFERROR(VLOOKUP(D15,'Fertilizer Library'!$A:$B,2,FALSE),"") | J15: =IFERROR(VLOOKUP(H15,'Fertilizer Library'!$A:$B,2,FALSE),"") | M15: =IFERROR(VLOOKUP(K15,'Fertilizer Library'!$A:$B,2,FALSE),"") | P15: =IFERROR(VLOOKUP(N15,'Fertilizer Library'!$A:$B,2,FALSE),"")

Sheet Project Inputs
A1: Project Inputs
A2: Activity data per monitoring year (one row per farm-year).
A4: Farm / unit | B4: Year | C4: Area (ha) | D4: Organic fert | H4: Synthetic fert 1 | K4: Synthetic fert 2 | N4: Synthetic fert 3 | Q4: Fuel | S4: Residue burnt (kg) | T4: N-fixing crop residue
D5: Name | E5: Mass (t) | F5: N (t N/t) | G5: Interval (yr) | H5: Name | I5: Mass (t) | J5: N (t N/t) | K5: Name | L5: Mass (t) | M5: N (t N/t) | N5: Name | O5: Mass (t) | P5: N (t N/t) | Q5: Diesel (L) | R5: Gasoline (L) | T5: Dry matter (t) | U5: N (t N/t d.m.)
A6: Farm_A | B6: 2025 | C6: 50 | E6: 0 | F6: =IFERROR(VLOOKUP(D6,'Fertilizer Library'!$A:$B,2,FALSE),"") | G6: 10 | H6: UAN / Uran 32-0-0 | I6: 30 | J6: =IFERROR(VLOOKUP(H6,'Fertilizer Library'!$A:$B,2,FALSE),"") -> 0.32 | K6: N-P-K 8-0-8 | L6: 20 | M6: =IFERROR(VLOOKUP(K6,'Fertilizer Library'!$A:$B,2,FALSE),"") -> 0.08 | P6: =IFERROR(VLOOKUP(N6,'Fertilizer Library'!$A:$B,2,FALSE),"") | Q6: 7500 | S6: 0 | T6: 0
A7: Farm_B | B7: 2025 | C7: 30 | D7: Manure (cattle, solid) | E7: 130 | F7: =IFERROR(VLOOKUP(D7,'Fertilizer Library'!$A:$B,2,FALSE),"") -> 0.006 | G7: 1 | H7: Ammonium sulphate 21-0-0 | I7: 22 | J7: =IFERROR(VLOOKUP(H7,'Fertilizer Library'!$A:$B,2,FALSE),"") -> 0.21 | M7: =IFERROR(VLOOKUP(K7,'Fertilizer Library'!$A:$B,2,FALSE),"") | P7: =IFERROR(VLOOKUP(N7,'Fertilizer Library'!$A:$B,2,FALSE),"") | Q7: 4600 | S7: 0 | T7: 2 | U7: 0.02
F8: =IFERROR(VLOOKUP(D8,'Fertilizer Library'!$A:$B,2,FALSE),"") | J8: =IFERROR(VLOOKUP(H8,'Fertilizer Library'!$A:$B,2,FALSE),"") | M8: =IFERROR(VLOOKUP(K8,'Fertilizer Library'!$A:$B,2,FALSE),"") | P8: =IFERROR(VLOOKUP(N8,'Fertilizer Library'!$A:$B,2,FALSE),"")
F9: =IFERROR(VLOOKUP(D9,'Fertilizer Library'!$A:$B,2,FALSE),"") | J9: =IFERROR(VLOOKUP(H9,'Fertilizer Library'!$A:$B,2,FALSE),"") | M9: =IFERROR(VLOOKUP(K9,'Fertilizer Library'!$A:$B,2,FALSE),"") | P9: =IFERROR(VLOOKUP(N9,'Fertilizer Library'!$A:$B,2,FALSE),"")
F10: =IFERROR(VLOOKUP(D10,'Fertilizer Library'!$A:$B,2,FALSE),"") | J10: =IFERROR(VLOOKUP(H10,'Fertilizer Library'!$A:$B,2,FALSE),"") | M10: =IFERROR(VLOOKUP(K10,'Fertilizer Library'!$A:$B,2,FALSE),"") | P10: =IFERROR(VLOOKUP(N10,'Fertilizer Library'!$A:$B,2,FALSE),"")
F11: =IFERROR(VLOOKUP(D11,'Fertilizer Library'!$A:$B,2,FALSE),"") | J11: =IFERROR(VLOOKUP(H11,'Fertilizer Library'!$A:$B,2,FALSE),"") | M11: =IFERROR(VLOOKUP(K11,'Fertilizer Library'!$A:$B,2,FALSE),"") | P11: =IFERROR(VLOOKUP(N11,'Fertilizer Library'!$A:$B,2,FALSE),"")

Sheet Baseline Emissions
A1: Baseline Emissions
A2: ="▶ Soil N₂O approach = "&'Fixed Parameters'!$B$7&IF('Fixed Parameters'!$B$7="QA3"," → soil N₂O (fertilizer + N-fixing) IS COUNTED on this sheet (QA3 default-factor)."," → soil N₂O is EXCLUDED here and taken from the QA1 model (SOC Removals sheet) — no double-counting.") -> ▶ Soil N₂O approach = QA3 → soil N₂O (fertilizer + N-fixing) IS COUNTED on this sheet (QA3 default-factor).
A3: Farm / unit | B3: Year | C3: Area (ha) | D3: FSN (t N) | E3: FON (t N) | F3: N2O direct (tCO2e/ha) | G3: N2O volat (tCO2e) | H3: N2O leach (tCO2e) | I3: N2O indirect (tCO2e/ha) | J3: N2O fert (tCO2e/ha) | K3: CO2 fuel (tCO2e/ha) | L3: N2O burn (tCO2e/ha) | M3: N2O Nfix (tCO2e/ha) | N3: TOTAL (tCO2e/ha) | O3: TOTAL (tCO2e)
A4: =IF('Baseline Inputs'!A6="","",'Baseline Inputs'!A6) -> Farm_A | B4: ='Baseline Inputs'!B6 -> 2022 | C4: =IF('Baseline Inputs'!A6="","",'Baseline Inputs'!C6) -> 50 | D4: =IF(OR('Baseline Inputs'!A6="",N('Baseline Inputs'!C6)=0),"",(N('Baseline Inputs'!I6)*N('Baseline Inputs'!J6)+N('Baseline Inputs'!L6)*N('Baseline Inputs'!M6)+N('Baseline Inputs'!O6)*N('Baseline Inputs'!P6))) -> 14.8 | E4: =IF(OR('Baseline Inputs'!A6="",N('Baseline Inputs'!C6)=0),"",(N('Baseline Inputs'!E6)/IF(N('Baseline Inputs'!G6)=0,1,N('Baseline Inputs'!G6))*N('Baseline Inputs'!F6))) -> 0.75 | F4: =IF(OR('Baseline Inputs'!A6="",N('Baseline Inputs'!C6)=0),"",((D4+E4)*'Fixed Parameters'!$B$16*(44/28)*'Fixed Parameters'!$B$11)/C4) -> 1.6836207 | G4: =IF(OR('Baseline Inputs'!A6="",N('Baseline Inputs'!C6)=0),"",((D4*'Fixed Parameters'!$B$17)+(E4*'Fixed Parameters'!$B$18))*'Fixed Parameters'!$B$19*(44/28)*'Fixed Parameters'!$B$11) -> 10.409465 | H4: =IF(OR('Baseline Inputs'!A6="",N('Baseline Inputs'!C6)=0),"",(D4+E4)*'Fixed Parameters'!$B$21*'Fixed Parameters'!$B$22*(44/28)*'Fixed Parameters'!$B$11) -> 17.095226 | I4: =IF(OR('Baseline Inputs'!A6="",N('Baseline Inputs'!C6)=0),"",(G4+H4)/C4) -> 0.55009381 | J4: =IF(OR('Baseline Inputs'!A6="",N('Baseline Inputs'!C6)=0),"",F4+I4) -> 2.2337145 | K4: =IF(OR('Baseline Inputs'!A6="",N('Baseline Inputs'!C6)=0),"",(N('Baseline Inputs'!Q6)*'Fixed Parameters'!$B$9+N('Baseline Inputs'!R6)*'Fixed Parameters'!$B$10)/C4) -> 0.51948 | L4: =IF(OR('Baseline Inputs'!A6="",N('Baseline Inputs'!C6)=0),"",('Fixed Parameters'!$B$11*N('Baseline Inputs'!S6)*'Fixed Parameters'!$B$23*'Fixed Parameters'!$B$24)/1000000/C4) -> 0 | M4: =IF(OR('Baseline Inputs'!A6="",N('Baseline Inputs'!C6)=0),"",(N('Baseline Inputs'!T6)*N('Baseline Inputs'!U6)*'Fixed Parameters'!$B$16*(44/28)*'Fixed Parameters'!$B$11)/C4) -> 0 | N4: =IF(OR('Baseline Inputs'!A6="",N('Baseline Inputs'!C6)=0),"",K4+L4+IF('Fixed Parameters'!$B$7="QA3",J4+M4,0)) -> 2.7531945 | O4: =IF(OR('Baseline Inputs'!A6="",N('Baseline Inputs'!C6)=0),"",N4*C4) -> 137.65973
A5: =IF('Baseline Inputs'!A7="","",'Baseline Inputs'!A7) -> Farm_A | B5: ='Baseline Inputs'!B7 -> 2023 | C5: =IF('Baseline Inputs'!A7="","",'Baseline Inputs'!C7) -> 50 | D5: =IF(OR('Baseline Inputs'!A7="",N('Baseline Inputs'!C7)=0),"",(N('Baseline Inputs'!I7)*N('Baseline Inputs'!J7)+N('Baseline Inputs'!L7)*N('Baseline Inputs'!M7)+N('Baseline Inputs'!O7)*N('Baseline Inputs'!P7))) -> 15.68 | E5: =IF(OR('Baseline Inputs'!A7="",N('Baseline Inputs'!C7)=0),"",(N('Baseline Inputs'!E7)/IF(N('Baseline Inputs'!G7)=0,1,N('Baseline Inputs'!G7))*N('Baseline Inputs'!F7))) -> 0 | F5: =IF(OR('Baseline Inputs'!A7="",N('Baseline Inputs'!C7)=0),"",((D5+E5)*'Fixed Parameters'!$B$16*(44/28)*'Fixed Parameters'!$B$11)/C5) -> 1.697696 | G5: =IF(OR('Baseline Inputs'!A7="",N('Baseline Inputs'!C7)=0),"",((D5*'Fixed Parameters'!$B$17)+(E5*'Fixed Parameters'!$B$18))*'Fixed Parameters'!$B$19*(44/28)*'Fixed Parameters'!$B$11) -> 10.055584 | H5: =IF(OR('Baseline Inputs'!A7="",N('Baseline Inputs'!C7)=0),"",(D5+E5)*'Fixed Parameters'!$B$21*'Fixed Parameters'!$B$22*(44/28)*'Fixed Parameters'!$B$11) -> 17.238144 | I5: =IF(OR('Baseline Inputs'!A7="",N('Baseline Inputs'!C7)=0),"",(G5+H5)/C5) -> 0.54587456 | J5: =IF(OR('Baseline Inputs'!A7="",N('Baseline Inputs'!C7)=0),"",F5+I5) -> 2.2435706 | K5: =IF(OR('Baseline Inputs'!A7="",N('Baseline Inputs'!C7)=0),"",(N('Baseline Inputs'!Q7)*'Fixed Parameters'!$B$9+N('Baseline Inputs'!R7)*'Fixed Parameters'!$B$10)/C5) -> 0.531024 | L5: =IF(OR('Baseline Inputs'!A7="",N('Baseline Inputs'!C7)=0),"",('Fixed Parameters'!$B$11*N('Baseline Inputs'!S7)*'Fixed Parameters'!$B$23*'Fixed Parameters'!$B$24)/1000000/C5) -> 0 | M5: =IF(OR('Baseline Inputs'!A7="",N('Baseline Inputs'!C7)=0),"",(N('Baseline Inputs'!T7)*N('Baseline Inputs'!U7)*'Fixed Parameters'!$B$16*(44/28)*'Fixed Parameters'!$B$11)/C5) -> 0 | N5: =IF(OR('Baseline Inputs'!A7="",N('Baseline Inputs'!C7)=0),"",K5+L5+IF('Fixed Parameters'!$B$7="QA3",J5+M5,0)) -> 2.7745946 | O5: =IF(OR('Baseline Inputs'!A7="",N('Baseline Inputs'!C7)=0),"",N5*C5) -> 138.72973
A6: =IF('Baseline Inputs'!A8="","",'Baseline Inputs'!A8) -> Farm_A | B6: ='Baseline Inputs'!B8 -> 2024 | C6: =IF('Baseline Inputs'!A8="","",'Baseline Inputs'!C8) -> 50 | D6: =IF(OR('Baseline Inputs'!A8="",N('Baseline Inputs'!C8)=0),"",(N('Baseline Inputs'!I8)*N('Baseline Inputs'!J8)+N('Baseline Inputs'!L8)*N('Baseline Inputs'!M8)+N('Baseline Inputs'!O8)*N('Baseline Inputs'!P8))) -> 14.14 | E6: =IF(OR('Baseline Inputs'!A8="",N('Baseline Inputs'!C8)=0),"",(N('Baseline Inputs'!E8)/IF(N('Baseline Inputs'!G8)=0,1,N('Baseline Inputs'!G8))*N('Baseline Inputs'!F8))) -> 0 | F6: =IF(OR('Baseline Inputs'!A8="",N('Baseline Inputs'!C8)=0),"",((D6+E6)*'Fixed Parameters'!$B$16*(44/28)*'Fixed Parameters'!$B$11)/C6) -> 1.530958 | G6: =IF(OR('Baseline Inputs'!A8="",N('Baseline Inputs'!C8)=0),"",((D6*'Fixed Parameters'!$B$17)+(E6*'Fixed Parameters'!$B$18))*'Fixed Parameters'!$B$19*(44/28)*'Fixed Parameters'!$B$11) -> 9.067982 | H6: =IF(OR('Baseline Inputs'!A8="",N('Baseline Inputs'!C8)=0),"",(D6+E6)*'Fixed Parameters'!$B$21*'Fixed Parameters'!$B$22*(44/28)*'Fixed Parameters'!$B$11) -> 15.545112 | I6: =IF(OR('Baseline Inputs'!A8="",N('Baseline Inputs'!C8)=0),"",(G6+H6)/C6) -> 0.49226188 | J6: =IF(OR('Baseline Inputs'!A8="",N('Baseline Inputs'!C8)=0),"",F6+I6) -> 2.0232199 | K6: =IF(OR('Baseline Inputs'!A8="",N('Baseline Inputs'!C8)=0),"",(N('Baseline Inputs'!Q8)*'Fixed Parameters'!$B$9+N('Baseline Inputs'!R8)*'Fixed Parameters'!$B$10)/C6) -> 0.507936 | L6: =IF(OR('Baseline Inputs'!A8="",N('Baseline Inputs'!C8)=0),"",('Fixed Parameters'!$B$11*N('Baseline Inputs'!S8)*'Fixed Parameters'!$B$23*'Fixed Parameters'!$B$24)/1000000/C6) -> 0 | M6: =IF(OR('Baseline Inputs'!A8="",N('Baseline Inputs'!C8)=0),"",(N('Baseline Inputs'!T8)*N('Baseline Inputs'!U8)*'Fixed Parameters'!$B$16*(44/28)*'Fixed Parameters'!$B$11)/C6) -> 0 | N6: =IF(OR('Baseline Inputs'!A8="",N('Baseline Inputs'!C8)=0),"",K6+L6+IF('Fixed Parameters'!$B$7="QA3",J6+M6,0)) -> 2.5311559 | O6: =IF(OR('Baseline Inputs'!A8="",N('Baseline Inputs'!C8)=0),"",N6*C6) -> 126.55779
A7: =IF('Baseline Inputs'!A9="","",'Baseline Inputs'!A9) -> Farm_B | B7: ='Baseline Inputs'!B9 -> 2022 | C7: =IF('Baseline Inputs'!A9="","",'Baseline Inputs'!C9) -> 30 | D7: =IF(OR('Baseline Inputs'!A9="",N('Baseline Inputs'!C9)=0),"",(N('Baseline Inputs'!I9)*N('Baseline Inputs'!J9)+N('Baseline Inputs'!L9)*N('Baseline Inputs'!M9)+N('Baseline Inputs'!O9)*N('Baseline Inputs'!P9))) -> 6.3 | E7: =IF(OR('Baseline Inputs'!A9="",N('Baseline Inputs'!C9)=0),"",(N('Baseline Inputs'!E9)/IF(N('Baseline Inputs'!G9)=0,1,N('Baseline Inputs'!G9))*N('Baseline Inputs'!F9))) -> 0.72 | F7: =IF(OR('Baseline Inputs'!A9="",N('Baseline Inputs'!C9)=0),"",((D7+E7)*'Fixed Parameters'!$B$16*(44/28)*'Fixed Parameters'!$B$11)/C7) -> 1.2667757 | G7: =IF(OR('Baseline Inputs'!A9="",N('Baseline Inputs'!C9)=0),"",((D7*'Fixed Parameters'!$B$17)+(E7*'Fixed Parameters'!$B$18))*'Fixed Parameters'!$B$19*(44/28)*'Fixed Parameters'!$B$11) -> 4.921686 | H7: =IF(OR('Baseline Inputs'!A9="",N('Baseline Inputs'!C9)=0),"",(D7+E7)*'Fixed Parameters'!$B$21*'Fixed Parameters'!$B$22*(44/28)*'Fixed Parameters'!$B$11) -> 7.7175874 | I7: =IF(OR('Baseline Inputs'!A9="",N('Baseline Inputs'!C9)=0),"",(G7+H7)/C7) -> 0.42130911 | J7: =IF(OR('Baseline Inputs'!A9="",N('Baseline Inputs'!C9)=0),"",F7+I7) -> 1.6880848 | K7: =IF(OR('Baseline Inputs'!A9="",N('Baseline Inputs'!C9)=0),"",(N('Baseline Inputs'!Q9)*'Fixed Parameters'!$B$9+N('Baseline Inputs'!R9)*'Fixed Parameters'!$B$10)/C7) -> 0.51948 | L7: =IF(OR('Baseline Inputs'!A9="",N('Baseline Inputs'!C9)=0),"",('Fixed Parameters'!$B$11*N('Baseline Inputs'!S9)*'Fixed Parameters'!$B$23*'Fixed Parameters'!$B$24)/1000000/C7) -> 0.00046375 | M7: =IF(OR('Baseline Inputs'!A9="",N('Baseline Inputs'!C9)=0),"",(N('Baseline Inputs'!T9)*N('Baseline Inputs'!U9)*'Fixed Parameters'!$B$16*(44/28)*'Fixed Parameters'!$B$11)/C7) -> 0.0072180952 | N7: =IF(OR('Baseline Inputs'!A9="",N('Baseline Inputs'!C9)=0),"",K7+L7+IF('Fixed Parameters'!$B$7="QA3",J7+M7,0)) -> 2.2152467 | O7: =IF(OR('Baseline Inputs'!A9="",N('Baseline Inputs'!C9)=0),"",N7*C7) -> 66.4574
A8: =IF('Baseline Inputs'!A10="","",'Baseline Inputs'!A10) -> Farm_B | B8: ='Baseline Inputs'!B10 -> 2023 | C8: =IF('Baseline Inputs'!A10="","",'Baseline Inputs'!C10) -> 30 | D8: =IF(OR('Baseline Inputs'!A10="",N('Baseline Inputs'!C10)=0),"",(N('Baseline Inputs'!I10)*N('Baseline Inputs'!J10)+N('Baseline Inputs'!L10)*N('Baseline Inputs'!M10)+N('Baseline Inputs'!O10)*N('Baseline Inputs'!P10))) -> 6.72 | E8: =IF(OR('Baseline Inputs'!A10="",N('Baseline Inputs'!C10)=0),"",(N('Baseline Inputs'!E10)/IF(N('Baseline Inputs'!G10)=0,1,N('Baseline Inputs'!G10))*N('Baseline Inputs'!F10))) -> 0.66 | F8: =IF(OR('Baseline Inputs'!A10="",N('Baseline Inputs'!C10)=0),"",((D8+E8)*'Fixed Parameters'!$B$16*(44/28)*'Fixed Parameters'!$B$11)/C8) -> 1.3317386 | G8: =IF(OR('Baseline Inputs'!A10="",N('Baseline Inputs'!C10)=0),"",((D8*'Fixed Parameters'!$B$17)+(E8*'Fixed Parameters'!$B$18))*'Fixed Parameters'!$B$19*(44/28)*'Fixed Parameters'!$B$11) -> 5.117574 | H8: =IF(OR('Baseline Inputs'!A10="",N('Baseline Inputs'!C10)=0),"",(D8+E8)*'Fixed Parameters'!$B$21*'Fixed Parameters'!$B$22*(44/28)*'Fixed Parameters'!$B$11) -> 8.1133611 | I8: =IF(OR('Baseline Inputs'!A10="",N('Baseline Inputs'!C10)=0),"",(G8+H8)/C8) -> 0.44103117 | J8: =IF(OR('Baseline Inputs'!A10="",N('Baseline Inputs'!C10)=0),"",F8+I8) -> 1.7727697 | K8: =IF(OR('Baseline Inputs'!A10="",N('Baseline Inputs'!C10)=0),"",(N('Baseline Inputs'!Q10)*'Fixed Parameters'!$B$9+N('Baseline Inputs'!R10)*'Fixed Parameters'!$B$10)/C8) -> 0.53872 | L8: =IF(OR('Baseline Inputs'!A10="",N('Baseline Inputs'!C10)=0),"",('Fixed Parameters'!$B$11*N('Baseline Inputs'!S10)*'Fixed Parameters'!$B$23*'Fixed Parameters'!$B$24)/1000000/C8) -> 0.00043283333 | M8: =IF(OR('Baseline Inputs'!A10="",N('Baseline Inputs'!C10)=0),"",(N('Baseline Inputs'!T10)*N('Baseline Inputs'!U10)*'Fixed Parameters'!$B$16*(44/28)*'Fixed Parameters'!$B$11)/C8) -> 0.0079399048 | N8: =IF(OR('Baseline Inputs'!A10="",N('Baseline Inputs'!C10)=0),"",K8+L8+IF('Fixed Parameters'!$B$7="QA3",J8+M8,0)) -> 2.3198625 | O8: =IF(OR('Baseline Inputs'!A10="",N('Baseline Inputs'!C10)=0),"",N8*C8) -> 69.595874
A9: =IF('Baseline Inputs'!A11="","",'Baseline Inputs'!A11) -> Farm_B | B9: ='Baseline Inputs'!B11 -> 2024 | C9: =IF('Baseline Inputs'!A11="","",'Baseline Inputs'!C11) -> 30 | D9: =IF(OR('Baseline Inputs'!A11="",N('Baseline Inputs'!C11)=0),"",(N('Baseline Inputs'!I11)*N('Baseline Inputs'!J11)+N('Baseline Inputs'!L11)*N('Baseline Inputs'!M11)+N('Baseline Inputs'!O11)*N('Baseline Inputs'!P11))) -> 5.88 | E9: =IF(OR('Baseline Inputs'!A11="",N('Baseline Inputs'!C11)=0),"",(N('Baseline Inputs'!E11)/IF(N('Baseline Inputs'!G11)=0,1,N('Baseline Inputs'!G11))*N('Baseline Inputs'!F11))) -> 0.78 | F9: =IF(OR('Baseline Inputs'!A11="",N('Baseline Inputs'!C11)=0),"",((D9+E9)*'Fixed Parameters'!$B$16*(44/28)*'Fixed Parameters'!$B$11)/C9) -> 1.2018129 | G9: =IF(OR('Baseline Inputs'!A11="",N('Baseline Inputs'!C11)=0),"",((D9*'Fixed Parameters'!$B$17)+(E9*'Fixed Parameters'!$B$18))*'Fixed Parameters'!$B$19*(44/28)*'Fixed Parameters'!$B$11) -> 4.725798 | H9: =IF(OR('Baseline Inputs'!A11="",N('Baseline Inputs'!C11)=0),"",(D9+E9)*'Fixed Parameters'!$B$21*'Fixed Parameters'!$B$22*(44/28)*'Fixed Parameters'!$B$11) -> 7.3218137 | I9: =IF(OR('Baseline Inputs'!A11="",N('Baseline Inputs'!C11)=0),"",(G9+H9)/C9) -> 0.40158706 | J9: =IF(OR('Baseline Inputs'!A11="",N('Baseline Inputs'!C11)=0),"",F9+I9) -> 1.6033999 | K9: =IF(OR('Baseline Inputs'!A11="",N('Baseline Inputs'!C11)=0),"",(N('Baseline Inputs'!Q11)*'Fixed Parameters'!$B$9+N('Baseline Inputs'!R11)*'Fixed Parameters'!$B$10)/C9) -> 0.50024 | L9: =IF(OR('Baseline Inputs'!A11="",N('Baseline Inputs'!C11)=0),"",('Fixed Parameters'!$B$11*N('Baseline Inputs'!S11)*'Fixed Parameters'!$B$23*'Fixed Parameters'!$B$24)/1000000/C9) -> 0.00049466667 | M9: =IF(OR('Baseline Inputs'!A11="",N('Baseline Inputs'!C11)=0),"",(N('Baseline Inputs'!T11)*N('Baseline Inputs'!U11)*'Fixed Parameters'!$B$16*(44/28)*'Fixed Parameters'!$B$11)/C9) -> 0.0064962857 | N9: =IF(OR('Baseline Inputs'!A11="",N('Baseline Inputs'!C11)=0),"",K9+L9+IF('Fixed Parameters'!$B$7="QA3",J9+M9,0)) -> 2.1106309 | O9: =IF(OR('Baseline Inputs'!A11="",N('Baseline Inputs'!C11)=0),"",N9*C9) -> 63.318926
A10: =IF('Baseline Inputs'!A12="","",'Baseline Inputs'!A12) | B10: ='Baseline Inputs'!B12 -> 0 | C10: =IF('Baseline Inputs'!A12="","",'Baseline Inputs'!C12) | D10: =IF(OR('Baseline Inputs'!A12="",N('Baseline Inputs'!C12)=0),"",(N('Baseline Inputs'!I12)*N('Baseline Inputs'!J12)+N('Baseline Inputs'!L12)*N('Baseline Inputs'!M12)+N('Baseline Inputs'!O12)*N('Baseline Inputs'!P12))) | E10: =IF(OR('Baseline Inputs'!A12="",N('Baseline Inputs'!C12)=0),"",(N('Baseline Inputs'!E12)/IF(N('Baseline Inputs'!G12)=0,1,N('Baseline Inputs'!G12))*N('Baseline Inputs'!F12))) | F10: =IF(OR('Baseline Inputs'!A12="",N('Baseline Inputs'!C12)=0),"",((D10+E10)*'Fixed Parameters'!$B$16*(44/28)*'Fixed Parameters'!$B$11)/C10) | G10: =IF(OR('Baseline Inputs'!A12="",N('Baseline Inputs'!C12)=0),"",((D10*'Fixed Parameters'!$B$17)+(E10*'Fixed Parameters'!$B$18))*'Fixed Parameters'!$B$19*(44/28)*'Fixed Parameters'!$B$11) | H10: =IF(OR('Baseline Inputs'!A12="",N('Baseline Inputs'!C12)=0),"",(D10+E10)*'Fixed Parameters'!$B$21*'Fixed Parameters'!$B$22*(44/28)*'Fixed Parameters'!$B$11) | I10: =IF(OR('Baseline Inputs'!A12="",N('Baseline Inputs'!C12)=0),"",(G10+H10)/C10) | J10: =IF(OR('Baseline Inputs'!A12="",N('Baseline Inputs'!C12)=0),"",F10+I10) | K10: =IF(OR('Baseline Inputs'!A12="",N('Baseline Inputs'!C12)=0),"",(N('Baseline Inputs'!Q12)*'Fixed Parameters'!$B$9+N('Baseline Inputs'!R12)*'Fixed Parameters'!$B$10)/C10) | L10: =IF(OR('Baseline Inputs'!A12="",N('Baseline Inputs'!C12)=0),"",('Fixed Parameters'!$B$11*N('Baseline Inputs'!S12)*'Fixed Parameters'!$B$23*'Fixed Parameters'!$B$24)/1000000/C10) | M10: =IF(OR('Baseline Inputs'!A12="",N('Baseline Inputs'!C12)=0),"",(N('Baseline Inputs'!T12)*N('Baseline Inputs'!U12)*'Fixed Parameters'!$B$16*(44/28)*'Fixed Parameters'!$B$11)/C10) | N10: =IF(OR('Baseline Inputs'!A12="",N('Baseline Inputs'!C12)=0),"",K10+L10+IF('Fixed Parameters'!$B$7="QA3",J10+M10,0)) | O10: =IF(OR('Baseline Inputs'!A12="",N('Baseline Inputs'!C12)=0),"",N10*C10)
A11: =IF('Baseline Inputs'!A13="","",'Baseline Inputs'!A13) | B11: ='Baseline Inputs'!B13 -> 0 | C11: =IF('Baseline Inputs'!A13="","",'Baseline Inputs'!C13) | D11: =IF(OR('Baseline Inputs'!A13="",N('Baseline Inputs'!C13)=0),"",(N('Baseline Inputs'!I13)*N('Baseline Inputs'!J13)+N('Baseline Inputs'!L13)*N('Baseline Inputs'!M13)+N('Baseline Inputs'!O13)*N('Baseline Inputs'!P13))) | E11: =IF(OR('Baseline Inputs'!A13="",N('Baseline Inputs'!C13)=0),"",(N('Baseline Inputs'!E13)/IF(N('Baseline Inputs'!G13)=0,1,N('Baseline Inputs'!G13))*N('Baseline Inputs'!F13))) | F11: =IF(OR('Baseline Inputs'!A13="",N('Baseline Inputs'!C13)=0),"",((D11+E11)*'Fixed Parameters'!$B$16*(44/28)*'Fixed Parameters'!$B$11)/C11) | G11: =IF(OR('Baseline Inputs'!A13="",N('Baseline Inputs'!C13)=0),"",((D11*'Fixed Parameters'!$B$17)+(E11*'Fixed Parameters'!$B$18))*'Fixed Parameters'!$B$19*(44/28)*'Fixed Parameters'!$B$11) | H11: =IF(OR('Baseline Inputs'!A13="",N('Baseline Inputs'!C13)=0),"",(D11+E11)*'Fixed Parameters'!$B$21*'Fixed Parameters'!$B$22*(44/28)*'Fixed Parameters'!$B$11) | I11: =IF(OR('Baseline Inputs'!A13="",N('Baseline Inputs'!C13)=0),"",(G11+H11)/C11) | J11: =IF(OR('Baseline Inputs'!A13="",N('Baseline Inputs'!C13)=0),"",F11+I11) | K11: =IF(OR('Baseline Inputs'!A13="",N('Baseline Inputs'!C13)=0),"",(N('Baseline Inputs'!Q13)*'Fixed Parameters'!$B$9+N('Baseline Inputs'!R13)*'Fixed Parameters'!$B$10)/C11) | L11: =IF(OR('Baseline Inputs'!A13="",N('Baseline Inputs'!C13)=0),"",('Fixed Parameters'!$B$11*N('Baseline Inputs'!S13)*'Fixed Parameters'!$B$23*'Fixed Parameters'!$B$24)/1000000/C11) | M11: =IF(OR('Baseline Inputs'!A13="",N('Baseline Inputs'!C13)=0),"",(N('Baseline Inputs'!T13)*N('Baseline Inputs'!U13)*'Fixed Parameters'!$B$16*(44/28)*'Fixed Parameters'!$B$11)/C11) | N11: =IF(OR('Baseline Inputs'!A13="",N('Baseline Inputs'!C13)=0),"",K11+L11+IF('Fixed Parameters'!$B$7="QA3",J11+M11,0)) | O11: =IF(OR('Baseline Inputs'!A13="",N('Baseline Inputs'!C13)=0),"",N11*C11)
A12: =IF('Baseline Inputs'!A14="","",'Baseline Inputs'!A14) | B12: ='Baseline Inputs'!B14 -> 0 | C12: =IF('Baseline Inputs'!A14="","",'Baseline Inputs'!C14) | D12: =IF(OR('Baseline Inputs'!A14="",N('Baseline Inputs'!C14)=0),"",(N('Baseline Inputs'!I14)*N('Baseline Inputs'!J14)+N('Baseline Inputs'!L14)*N('Baseline Inputs'!M14)+N('Baseline Inputs'!O14)*N('Baseline Inputs'!P14))) | E12: =IF(OR('Baseline Inputs'!A14="",N('Baseline Inputs'!C14)=0),"",(N('Baseline Inputs'!E14)/IF(N('Baseline Inputs'!G14)=0,1,N('Baseline Inputs'!G14))*N('Baseline Inputs'!F14))) | F12: =IF(OR('Baseline Inputs'!A14="",N('Baseline Inputs'!C14)=0),"",((D12+E12)*'Fixed Parameters'!$B$16*(44/28)*'Fixed Parameters'!$B$11)/C12) | G12: =IF(OR('Baseline Inputs'!A14="",N('Baseline Inputs'!C14)=0),"",((D12*'Fixed Parameters'!$B$17)+(E12*'Fixed Parameters'!$B$18))*'Fixed Parameters'!$B$19*(44/28)*'Fixed Parameters'!$B$11) | H12: =IF(OR('Baseline Inputs'!A14="",N('Baseline Inputs'!C14)=0),"",(D12+E12)*'Fixed Parameters'!$B$21*'Fixed Parameters'!$B$22*(44/28)*'Fixed Parameters'!$B$11) | I12: =IF(OR('Baseline Inputs'!A14="",N('Baseline Inputs'!C14)=0),"",(G12+H12)/C12) | J12: =IF(OR('Baseline Inputs'!A14="",N('Baseline Inputs'!C14)=0),"",F12+I12) | K12: =IF(OR('Baseline Inputs'!A14="",N('Baseline Inputs'!C14)=0),"",(N('Baseline Inputs'!Q14)*'Fixed Parameters'!$B$9+N('Baseline Inputs'!R14)*'Fixed Parameters'!$B$10)/C12) | L12: =IF(OR('Baseline Inputs'!A14="",N('Baseline Inputs'!C14)=0),"",('Fixed Parameters'!$B$11*N('Baseline Inputs'!S14)*'Fixed Parameters'!$B$23*'Fixed Parameters'!$B$24)/1000000/C12) | M12: =IF(OR('Baseline Inputs'!A14="",N('Baseline Inputs'!C14)=0),"",(N('Baseline Inputs'!T14)*N('Baseline Inputs'!U14)*'Fixed Parameters'!$B$16*(44/28)*'Fixed Parameters'!$B$11)/C12) | N12: =IF(OR('Baseline Inputs'!A14="",N('Baseline Inputs'!C14)=0),"",K12+L12+IF('Fixed Parameters'!$B$7="QA3",J12+M12,0)) | O12: =IF(OR('Baseline Inputs'!A14="",N('Baseline Inputs'!C14)=0),"",N12*C12)
A13: =IF('Baseline Inputs'!A15="","",'Baseline Inputs'!A15) | B13: ='Baseline Inputs'!B15 -> 0 | C13: =IF('Baseline Inputs'!A15="","",'Baseline Inputs'!C15) | D13: =IF(OR('Baseline Inputs'!A15="",N('Baseline Inputs'!C15)=0),"",(N('Baseline Inputs'!I15)*N('Baseline Inputs'!J15)+N('Baseline Inputs'!L15)*N('Baseline Inputs'!M15)+N('Baseline Inputs'!O15)*N('Baseline Inputs'!P15))) | E13: =IF(OR('Baseline Inputs'!A15="",N('Baseline Inputs'!C15)=0),"",(N('Baseline Inputs'!E15)/IF(N('Baseline Inputs'!G15)=0,1,N('Baseline Inputs'!G15))*N('Baseline Inputs'!F15))) | F13: =IF(OR('Baseline Inputs'!A15="",N('Baseline Inputs'!C15)=0),"",((D13+E13)*'Fixed Parameters'!$B$16*(44/28)*'Fixed Parameters'!$B$11)/C13) | G13: =IF(OR('Baseline Inputs'!A15="",N('Baseline Inputs'!C15)=0),"",((D13*'Fixed Parameters'!$B$17)+(E13*'Fixed Parameters'!$B$18))*'Fixed Parameters'!$B$19*(44/28)*'Fixed Parameters'!$B$11) | H13: =IF(OR('Baseline Inputs'!A15="",N('Baseline Inputs'!C15)=0),"",(D13+E13)*'Fixed Parameters'!$B$21*'Fixed Parameters'!$B$22*(44/28)*'Fixed Parameters'!$B$11) | I13: =IF(OR('Baseline Inputs'!A15="",N('Baseline Inputs'!C15)=0),"",(G13+H13)/C13) | J13: =IF(OR('Baseline Inputs'!A15="",N('Baseline Inputs'!C15)=0),"",F13+I13) | K13: =IF(OR('Baseline Inputs'!A15="",N('Baseline Inputs'!C15)=0),"",(N('Baseline Inputs'!Q15)*'Fixed Parameters'!$B$9+N('Baseline Inputs'!R15)*'Fixed Parameters'!$B$10)/C13) | L13: =IF(OR('Baseline Inputs'!A15="",N('Baseline Inputs'!C15)=0),"",('Fixed Parameters'!$B$11*N('Baseline Inputs'!S15)*'Fixed Parameters'!$B$23*'Fixed Parameters'!$B$24)/1000000/C13) | M13: =IF(OR('Baseline Inputs'!A15="",N('Baseline Inputs'!C15)=0),"",(N('Baseline Inputs'!T15)*N('Baseline Inputs'!U15)*'Fixed Parameters'!$B$16*(44/28)*'Fixed Parameters'!$B$11)/C13) | N13: =IF(OR('Baseline Inputs'!A15="",N('Baseline Inputs'!C15)=0),"",K13+L13+IF('Fixed Parameters'!$B$7="QA3",J13+M13,0)) | O13: =IF(OR('Baseline Inputs'!A15="",N('Baseline Inputs'!C15)=0),"",N13*C13)

Sheet Project Emissions
A1: Project Emissions
A2: ="▶ Soil N₂O approach = "&'Fixed Parameters'!$B$7&IF('Fixed Parameters'!$B$7="QA3"," → soil N₂O (fertilizer + N-fixing) IS COUNTED on this sheet (QA3 default-factor)."," → soil N₂O is EXCLUDED here and taken from the QA1 model (SOC Removals sheet) — no double-counting.") -> ▶ Soil N₂O approach = QA3 → soil N₂O (fertilizer + N-fixing) IS COUNTED on this sheet (QA3 default-factor).
A3: Farm / unit | B3: Year | C3: Area (ha) | D3: FSN (t N) | E3: FON (t N) | F3: N2O direct (tCO2e/ha) | G3: N2O volat (tCO2e) | H3: N2O leach (tCO2e) | I3: N2O indirect (tCO2e/ha) | J3: N2O fert (tCO2e/ha) | K3: CO2 fuel (tCO2e/ha) | L3: N2O burn (tCO2e/ha) | M3: N2O Nfix (tCO2e/ha) | N3: TOTAL (tCO2e/ha) | O3: TOTAL (tCO2e)
A4: =IF('Project Inputs'!A6="","",'Project Inputs'!A6) -> Farm_A | B4: ='Project Inputs'!B6 -> 2025 | C4: =IF('Project Inputs'!A6="","",'Project Inputs'!C6) -> 50 | D4: =IF(OR('Project Inputs'!A6="",N('Project Inputs'!C6)=0),"",(N('Project Inputs'!I6)*N('Project Inputs'!J6)+N('Project Inputs'!L6)*N('Project Inputs'!M6)+N('Project Inputs'!O6)*N('Project Inputs'!P6))) -> 11.2 | E4: =IF(OR('Project Inputs'!A6="",N('Project Inputs'!C6)=0),"",(N('Project Inputs'!E6)/IF(N('Project Inputs'!G6)=0,1,N('Project Inputs'!G6))*N('Project Inputs'!F6))) -> 0 | F4: =IF(OR('Project Inputs'!A6="",N('Project Inputs'!C6)=0),"",((D4+E4)*'Fixed Parameters'!$B$16*(44/28)*'Fixed Parameters'!$B$11)/C4) -> 1.21264 | G4: =IF(OR('Project Inputs'!A6="",N('Project Inputs'!C6)=0),"",((D4*'Fixed Parameters'!$B$17)+(E4*'Fixed Parameters'!$B$18))*'Fixed Parameters'!$B$19*(44/28)*'Fixed Parameters'!$B$11) -> 7.18256 | H4: =IF(OR('Project Inputs'!A6="",N('Project Inputs'!C6)=0),"",(D4+E4)*'Fixed Parameters'!$B$21*'Fixed Parameters'!$B$22*(44/28)*'Fixed Parameters'!$B$11) -> 12.31296 | I4: =IF(OR('Project Inputs'!A6="",N('Project Inputs'!C6)=0),"",(G4+H4)/C4) -> 0.3899104 | J4: =IF(OR('Project Inputs'!A6="",N('Project Inputs'!C6)=0),"",F4+I4) -> 1.6025504 | K4: =IF(OR('Project Inputs'!A6="",N('Project Inputs'!C6)=0),"",(N('Project Inputs'!Q6)*'Fixed Parameters'!$B$9+N('Project Inputs'!R6)*'Fixed Parameters'!$B$10)/C4) -> 0.4329 | L4: =IF(OR('Project Inputs'!A6="",N('Project Inputs'!C6)=0),"",('Fixed Parameters'!$B$11*N('Project Inputs'!S6)*'Fixed Parameters'!$B$23*'Fixed Parameters'!$B$24)/1000000/C4) -> 0 | M4: =IF(OR('Project Inputs'!A6="",N('Project Inputs'!C6)=0),"",(N('Project Inputs'!T6)*N('Project Inputs'!U6)*'Fixed Parameters'!$B$16*(44/28)*'Fixed Parameters'!$B$11)/C4) -> 0 | N4: =IF(OR('Project Inputs'!A6="",N('Project Inputs'!C6)=0),"",K4+L4+IF('Fixed Parameters'!$B$7="QA3",J4+M4,0)) -> 2.0354504 | O4: =IF(OR('Project Inputs'!A6="",N('Project Inputs'!C6)=0),"",N4*C4) -> 101.77252
A5: =IF('Project Inputs'!A7="","",'Project Inputs'!A7) -> Farm_B | B5: ='Project Inputs'!B7 -> 2025 | C5: =IF('Project Inputs'!A7="","",'Project Inputs'!C7) -> 30 | D5: =IF(OR('Project Inputs'!A7="",N('Project Inputs'!C7)=0),"",(N('Project Inputs'!I7)*N('Project Inputs'!J7)+N('Project Inputs'!L7)*N('Project Inputs'!M7)+N('Project Inputs'!O7)*N('Project Inputs'!P7))) -> 4.62 | E5: =IF(OR('Project Inputs'!A7="",N('Project Inputs'!C7)=0),"",(N('Project Inputs'!E7)/IF(N('Project Inputs'!G7)=0,1,N('Project Inputs'!G7))*N('Project Inputs'!F7))) -> 0.78 | F5: =IF(OR('Project Inputs'!A7="",N('Project Inputs'!C7)=0),"",((D5+E5)*'Fixed Parameters'!$B$16*(44/28)*'Fixed Parameters'!$B$11)/C5) -> 0.97444286 | G5: =IF(OR('Project Inputs'!A7="",N('Project Inputs'!C7)=0),"",((D5*'Fixed Parameters'!$B$17)+(E5*'Fixed Parameters'!$B$18))*'Fixed Parameters'!$B$19*(44/28)*'Fixed Parameters'!$B$11) -> 3.91776 | H5: =IF(OR('Project Inputs'!A7="",N('Project Inputs'!C7)=0),"",(D5+E5)*'Fixed Parameters'!$B$21*'Fixed Parameters'!$B$22*(44/28)*'Fixed Parameters'!$B$11) -> 5.9366057 | I5: =IF(OR('Project Inputs'!A7="",N('Project Inputs'!C7)=0),"",(G5+H5)/C5) -> 0.32847886 | J5: =IF(OR('Project Inputs'!A7="",N('Project Inputs'!C7)=0),"",F5+I5) -> 1.3029217 | K5: =IF(OR('Project Inputs'!A7="",N('Project Inputs'!C7)=0),"",(N('Project Inputs'!Q7)*'Fixed Parameters'!$B$9+N('Project Inputs'!R7)*'Fixed Parameters'!$B$10)/C5) -> 0.44252 | L5: =IF(OR('Project Inputs'!A7="",N('Project Inputs'!C7)=0),"",('Fixed Parameters'!$B$11*N('Project Inputs'!S7)*'Fixed Parameters'!$B$23*'Fixed Parameters'!$B$24)/1000000/C5) -> 0 | M5: =IF(OR('Project Inputs'!A7="",N('Project Inputs'!C7)=0),"",(N('Project Inputs'!T7)*N('Project Inputs'!U7)*'Fixed Parameters'!$B$16*(44/28)*'Fixed Parameters'!$B$11)/C5) -> 0.0072180952 | N5: =IF(OR('Project Inputs'!A7="",N('Project Inputs'!C7)=0),"",K5+L5+IF('Fixed Parameters'!$B$7="QA3",J5+M5,0)) -> 1.7526598 | O5: =IF(OR('Project Inputs'!A7="",N('Project Inputs'!C7)=0),"",N5*C5) -> 52.579794
A6: =IF('Project Inputs'!A8="","",'Project Inputs'!A8) | B6: ='Project Inputs'!B8 -> 0 | C6: =IF('Project Inputs'!A8="","",'Project Inputs'!C8) | D6: =IF(OR('Project Inputs'!A8="",N('Project Inputs'!C8)=0),"",(N('Project Inputs'!I8)*N('Project Inputs'!J8)+N('Project Inputs'!L8)*N('Project Inputs'!M8)+N('Project Inputs'!O8)*N('Project Inputs'!P8))) | E6: =IF(OR('Project Inputs'!A8="",N('Project Inputs'!C8)=0),"",(N('Project Inputs'!E8)/IF(N('Project Inputs'!G8)=0,1,N('Project Inputs'!G8))*N('Project Inputs'!F8))) | F6: =IF(OR('Project Inputs'!A8="",N('Project Inputs'!C8)=0),"",((D6+E6)*'Fixed Parameters'!$B$16*(44/28)*'Fixed Parameters'!$B$11)/C6) | G6: =IF(OR('Project Inputs'!A8="",N('Project Inputs'!C8)=0),"",((D6*'Fixed Parameters'!$B$17)+(E6*'Fixed Parameters'!$B$18))*'Fixed Parameters'!$B$19*(44/28)*'Fixed Parameters'!$B$11) | H6: =IF(OR('Project Inputs'!A8="",N('Project Inputs'!C8)=0),"",(D6+E6)*'Fixed Parameters'!$B$21*'Fixed Parameters'!$B$22*(44/28)*'Fixed Parameters'!$B$11) | I6: =IF(OR('Project Inputs'!A8="",N('Project Inputs'!C8)=0),"",(G6+H6)/C6) | J6: =IF(OR('Project Inputs'!A8="",N('Project Inputs'!C8)=0),"",F6+I6) | K6: =IF(OR('Project Inputs'!A8="",N('Project Inputs'!C8)=0),"",(N('Project Inputs'!Q8)*'Fixed Parameters'!$B$9+N('Project Inputs'!R8)*'Fixed Parameters'!$B$10)/C6) | L6: =IF(OR('Project Inputs'!A8="",N('Project Inputs'!C8)=0),"",('Fixed Parameters'!$B$11*N('Project Inputs'!S8)*'Fixed Parameters'!$B$23*'Fixed Parameters'!$B$24)/1000000/C6) | M6: =IF(OR('Project Inputs'!A8="",N('Project Inputs'!C8)=0),"",(N('Project Inputs'!T8)*N('Project Inputs'!U8)*'Fixed Parameters'!$B$16*(44/28)*'Fixed Parameters'!$B$11)/C6) | N6: =IF(OR('Project Inputs'!A8="",N('Project Inputs'!C8)=0),"",K6+L6+IF('Fixed Parameters'!$B$7="QA3",J6+M6,0)) | O6: =IF(OR('Project Inputs'!A8="",N('Project Inputs'!C8)=0),"",N6*C6)
A7: =IF('Project Inputs'!A9="","",'Project Inputs'!A9) | B7: ='Project Inputs'!B9 -> 0 | C7: =IF('Project Inputs'!A9="","",'Project Inputs'!C9) | D7: =IF(OR('Project Inputs'!A9="",N('Project Inputs'!C9)=0),"",(N('Project Inputs'!I9)*N('Project Inputs'!J9)+N('Project Inputs'!L9)*N('Project Inputs'!M9)+N('Project Inputs'!O9)*N('Project Inputs'!P9))) | E7: =IF(OR('Project Inputs'!A9="",N('Project Inputs'!C9)=0),"",(N('Project Inputs'!E9)/IF(N('Project Inputs'!G9)=0,1,N('Project Inputs'!G9))*N('Project Inputs'!F9))) | F7: =IF(OR('Project Inputs'!A9="",N('Project Inputs'!C9)=0),"",((D7+E7)*'Fixed Parameters'!$B$16*(44/28)*'Fixed Parameters'!$B$11)/C7) | G7: =IF(OR('Project Inputs'!A9="",N('Project Inputs'!C9)=0),"",((D7*'Fixed Parameters'!$B$17)+(E7*'Fixed Parameters'!$B$18))*'Fixed Parameters'!$B$19*(44/28)*'Fixed Parameters'!$B$11) | H7: =IF(OR('Project Inputs'!A9="",N('Project Inputs'!C9)=0),"",(D7+E7)*'Fixed Parameters'!$B$21*'Fixed Parameters'!$B$22*(44/28)*'Fixed Parameters'!$B$11) | I7: =IF(OR('Project Inputs'!A9="",N('Project Inputs'!C9)=0),"",(G7+H7)/C7) | J7: =IF(OR('Project Inputs'!A9="",N('Project Inputs'!C9)=0),"",F7+I7) | K7: =IF(OR('Project Inputs'!A9="",N('Project Inputs'!C9)=0),"",(N('Project Inputs'!Q9)*'Fixed Parameters'!$B$9+N('Project Inputs'!R9)*'Fixed Parameters'!$B$10)/C7) | L7: =IF(OR('Project Inputs'!A9="",N('Project Inputs'!C9)=0),"",('Fixed Parameters'!$B$11*N('Project Inputs'!S9)*'Fixed Parameters'!$B$23*'Fixed Parameters'!$B$24)/1000000/C7) | M7: =IF(OR('Project Inputs'!A9="",N('Project Inputs'!C9)=0),"",(N('Project Inputs'!T9)*N('Project Inputs'!U9)*'Fixed Parameters'!$B$16*(44/28)*'Fixed Parameters'!$B$11)/C7) | N7: =IF(OR('Project Inputs'!A9="",N('Project Inputs'!C9)=0),"",K7+L7+IF('Fixed Parameters'!$B$7="QA3",J7+M7,0)) | O7: =IF(OR('Project Inputs'!A9="",N('Project Inputs'!C9)=0),"",N7*C7)
A8: =IF('Project Inputs'!A10="","",'Project Inputs'!A10) | B8: ='Project Inputs'!B10 -> 0 | C8: =IF('Project Inputs'!A10="","",'Project Inputs'!C10) | D8: =IF(OR('Project Inputs'!A10="",N('Project Inputs'!C10)=0),"",(N('Project Inputs'!I10)*N('Project Inputs'!J10)+N('Project Inputs'!L10)*N('Project Inputs'!M10)+N('Project Inputs'!O10)*N('Project Inputs'!P10))) | E8: =IF(OR('Project Inputs'!A10="",N('Project Inputs'!C10)=0),"",(N('Project Inputs'!E10)/IF(N('Project Inputs'!G10)=0,1,N('Project Inputs'!G10))*N('Project Inputs'!F10))) | F8: =IF(OR('Project Inputs'!A10="",N('Project Inputs'!C10)=0),"",((D8+E8)*'Fixed Parameters'!$B$16*(44/28)*'Fixed Parameters'!$B$11)/C8) | G8: =IF(OR('Project Inputs'!A10="",N('Project Inputs'!C10)=0),"",((D8*'Fixed Parameters'!$B$17)+(E8*'Fixed Parameters'!$B$18))*'Fixed Parameters'!$B$19*(44/28)*'Fixed Parameters'!$B$11) | H8: =IF(OR('Project Inputs'!A10="",N('Project Inputs'!C10)=0),"",(D8+E8)*'Fixed Parameters'!$B$21*'Fixed Parameters'!$B$22*(44/28)*'Fixed Parameters'!$B$11) | I8: =IF(OR('Project Inputs'!A10="",N('Project Inputs'!C10)=0),"",(G8+H8)/C8) | J8: =IF(OR('Project Inputs'!A10="",N('Project Inputs'!C10)=0),"",F8+I8) | K8: =IF(OR('Project Inputs'!A10="",N('Project Inputs'!C10)=0),"",(N('Project Inputs'!Q10)*'Fixed Parameters'!$B$9+N('Project Inputs'!R10)*'Fixed Parameters'!$B$10)/C8) | L8: =IF(OR('Project Inputs'!A10="",N('Project Inputs'!C10)=0),"",('Fixed Parameters'!$B$11*N('Project Inputs'!S10)*'Fixed Parameters'!$B$23*'Fixed Parameters'!$B$24)/1000000/C8) | M8: =IF(OR('Project Inputs'!A10="",N('Project Inputs'!C10)=0),"",(N('Project Inputs'!T10)*N('Project Inputs'!U10)*'Fixed Parameters'!$B$16*(44/28)*'Fixed Parameters'!$B$11)/C8) | N8: =IF(OR('Project Inputs'!A10="",N('Project Inputs'!C10)=0),"",K8+L8+IF('Fixed Parameters'!$B$7="QA3",J8+M8,0)) | O8: =IF(OR('Project Inputs'!A10="",N('Project Inputs'!C10)=0),"",N8*C8)
A9: =IF('Project Inputs'!A11="","",'Project Inputs'!A11) | B9: ='Project Inputs'!B11 -> 0 | C9: =IF('Project Inputs'!A11="","",'Project Inputs'!C11) | D9: =IF(OR('Project Inputs'!A11="",N('Project Inputs'!C11)=0),"",(N('Project Inputs'!I11)*N('Project Inputs'!J11)+N('Project Inputs'!L11)*N('Project Inputs'!M11)+N('Project Inputs'!O11)*N('Project Inputs'!P11))) | E9: =IF(OR('Project Inputs'!A11="",N('Project Inputs'!C11)=0),"",(N('Project Inputs'!E11)/IF(N('Project Inputs'!G11)=0,1,N('Project Inputs'!G11))*N('Project Inputs'!F11))) | F9: =IF(OR('Project Inputs'!A11="",N('Project Inputs'!C11)=0),"",((D9+E9)*'Fixed Parameters'!$B$16*(44/28)*'Fixed Parameters'!$B$11)/C9) | G9: =IF(OR('Project Inputs'!A11="",N('Project Inputs'!C11)=0),"",((D9*'Fixed Parameters'!$B$17)+(E9*'Fixed Parameters'!$B$18))*'Fixed Parameters'!$B$19*(44/28)*'Fixed Parameters'!$B$11) | H9: =IF(OR('Project Inputs'!A11="",N('Project Inputs'!C11)=0),"",(D9+E9)*'Fixed Parameters'!$B$21*'Fixed Parameters'!$B$22*(44/28)*'Fixed Parameters'!$B$11) | I9: =IF(OR('Project Inputs'!A11="",N('Project Inputs'!C11)=0),"",(G9+H9)/C9) | J9: =IF(OR('Project Inputs'!A11="",N('Project Inputs'!C11)=0),"",F9+I9) | K9: =IF(OR('Project Inputs'!A11="",N('Project Inputs'!C11)=0),"",(N('Project Inputs'!Q11)*'Fixed Parameters'!$B$9+N('Project Inputs'!R11)*'Fixed Parameters'!$B$10)/C9) | L9: =IF(OR('Project Inputs'!A11="",N('Project Inputs'!C11)=0),"",('Fixed Parameters'!$B$11*N('Project Inputs'!S11)*'Fixed Parameters'!$B$23*'Fixed Parameters'!$B$24)/1000000/C9) | M9: =IF(OR('Project Inputs'!A11="",N('Project Inputs'!C11)=0),"",(N('Project Inputs'!T11)*N('Project Inputs'!U11)*'Fixed Parameters'!$B$16*(44/28)*'Fixed Parameters'!$B$11)/C9) | N9: =IF(OR('Project Inputs'!A11="",N('Project Inputs'!C11)=0),"",K9+L9+IF('Fixed Parameters'!$B$7="QA3",J9+M9,0)) | O9: =IF(OR('Project Inputs'!A11="",N('Project Inputs'!C11)=0),"",N9*C9)

Sheet Net Reductions
A1: Net Reductions
A2: Emission reductions = Baseline (3-yr avg, t CO2e/ha) − Project (t CO2e/ha), applied to project area. Leakage placeholder = 0 (Phase 2).
A3: Farm / unit | B3: Project area (ha) | C3: Baseline (tCO2e/ha) | D3: Project (tCO2e/ha) | E3: Δ per ha (tCO2e/ha) | F3: Gross ERR (tCO2e) | G3: Leakage (tCO2e) | H3: Net ERR (tCO2e) | I3: Δ CO2 fuel (tCO2e/ha) | J3: Δ N2O fert (tCO2e/ha)
A4: Farm_A | B4: =IFERROR(AVERAGEIFS('Project Emissions'!C$4:C$9,'Project Emissions'!$A$4:$A$9,A4),0) -> 50 | C4: =IFERROR(AVERAGEIFS('Baseline Emissions'!N$4:N$13,'Baseline Emissions'!$A$4:$A$13,A4),0) -> 2.686315 | D4: =IFERROR(AVERAGEIFS('Project Emissions'!N$4:N$9,'Project Emissions'!$A$4:$A$9,A4),0) -> 2.0354504 | E4: =C4-D4 -> 0.65086459 | F4: =E4*B4 -> 32.543229 | G4: 0 | H4: =F4-G4 -> 32.543229 | I4: =IFERROR(AVERAGEIFS('Baseline Emissions'!K$4:K$13,'Baseline Emissions'!$A$4:$A$13,A4)-AVERAGEIFS('Project Emissions'!K$4:K$9,'Project Emissions'!$A$4:$A$9,A4),0) -> 0.08658 | J4: =IFERROR(AVERAGEIFS('Baseline Emissions'!J$4:J$13,'Baseline Emissions'!$A$4:$A$13,A4)-AVERAGEIFS('Project Emissions'!J$4:J$9,'Project Emissions'!$A$4:$A$9,A4),0) -> 0.56428459
A5: Farm_B | B5: =IFERROR(AVERAGEIFS('Project Emissions'!C$4:C$9,'Project Emissions'!$A$4:$A$9,A5),0) -> 30 | C5: =IFERROR(AVERAGEIFS('Baseline Emissions'!N$4:N$13,'Baseline Emissions'!$A$4:$A$13,A5),0) -> 2.2152467 | D5: =IFERROR(AVERAGEIFS('Project Emissions'!N$4:N$9,'Project Emissions'!$A$4:$A$9,A5),0) -> 1.7526598 | E5: =C5-D5 -> 0.46258686 | F5: =E5*B5 -> 13.877606 | G5: 0 | H5: =F5-G5 -> 13.877606 | I5: =IFERROR(AVERAGEIFS('Baseline Emissions'!K$4:K$13,'Baseline Emissions'!$A$4:$A$13,A5)-AVERAGEIFS('Project Emissions'!K$4:K$9,'Project Emissions'!$A$4:$A$9,A5),0) -> 0.07696 | J5: =IFERROR(AVERAGEIFS('Baseline Emissions'!J$4:J$13,'Baseline Emissions'!$A$4:$A$13,A5)-AVERAGEIFS('Project Emissions'!J$4:J$9,'Project Emissions'!$A$4:$A$9,A5),0) -> 0.38516311
A6: TOTAL | B6: =SUM(B4:B5) -> 80 | F6: =SUM(F4:F5) -> 46.420835 | H6: =SUM(H4:H5) -> 46.420835

Sheet SOC Removals (QA1)
A1: SOC Removals — Quantification Approach 1 (Measure & Model)
A2: Hybrid model: soil-organic-carbon removals via a calibrated/validated model (per VMD0053). QA3 emission sources stay on the other sheets — keep each source on ONE approach across baseline & project, stratified separately (VM0042 §8.1).
A3: Enter MODEL OUTPUTS (purple): SOC stock change per scenario as t CO2e/ha/yr, positive = sequestration. Initial SOC measured at t=0; remeasure ≥ every 5 yr to true-up the model. Removals (eq 40/41) = project − baseline, after the model uncertainty deduction (§8.6 / VMD0053).
A4: Farm / unit | B4: Area (ha) | C4: Initial SOC (t C/ha, t=0) | D4: ΔSOC baseline (tCO2e/ha) | E4: ΔSOC project (tCO2e/ha) | F4: Net removal (tCO2e/ha) | G4: Model UNC deduction | H4: Net removal after UNC (/ha) | I4: Net removals (tCO2e) | J4: Note
A5: Farm_A | B5: 50 | C5: 35 | D5: 0.2 | E5: 1.4 | F5: =E5-D5 -> 1.2 | G5: 0.05 | H5: =F5*(1-G5) -> 1.14 | I5: =H5*B5 -> 57 | J5: Illustrative model output — replace with IME-approved model results.
A6: Farm_B | B6: 30 | C6: 28 | D6: 0.1 | E6: 1.1 | F6: =E6-D6 -> 1 | G6: 0.05 | H6: =F6*(1-G6) -> 0.95 | I6: =H6*B6 -> 28.5
A7: TOTAL SOC removals | B7: =SUM(B5:B6) -> 80 | I7: =SUM(I5:I6) -> 85.5
A9: Modeled soil N₂O (QA1) — populate ONLY if "Soil N2O approach" = QA1 (else leave blank; N₂O is then computed by QA3 on the emission sheets).
A10: Farm / unit | B10: Area (ha) | C10: Modeled N₂O baseline (tCO2e/ha) | D10: Modeled N₂O project (tCO2e/ha) | F10: N₂O reduction (tCO2e/ha) | G10: Model UNC deduction | H10: Net reduction after UNC (/ha) | I10: Net N₂O reduction (tCO2e) | J10: Note
A11: Farm_A | B11: =B5 -> 50 | F11: =IF(OR(C11="",D11=""),0,C11-D11) -> 0 | G11: 0.1 | H11: =F11*(1-G11) -> 0 | I11: =H11*B11 -> 0 | J11: Baseline − project soil N₂O from the model (tCO2e/ha).
A12: Farm_B | B12: =B6 -> 30 | F12: =IF(OR(C12="",D12=""),0,C12-D12) -> 0 | G12: 0.1 | H12: =F12*(1-G12) -> 0 | I12: =H12*B12 -> 0 | J12: Baseline − project soil N₂O from the model (tCO2e/ha).
A13: TOTAL N₂O reductions | I13: =SUM(I11:I12) -> 0

Sheet Leakage
A1: Leakage
A2: VM0042 v2.2 §8.4. 8.4.1 (organic amendments, eq 33) is computed automatically; 8.4.2/8.4.3/8.4.4 are entered with justification.
A3: 8.4.1 · New/additional organic amendments (eq 33): LE = additional mass (t) × C-content (t C/t) × 0.12 × 44/12
A4: Farm / unit | B4: Project OA (t/yr) | C4: Baseline OA (t/yr) | D4: Additional (t/yr) | E4: C content (t C/t) | F4: Exempt? | G4: Leakage LE_OA (t CO2e) | H4: Note
A5: Farm_A | B5: =SUMPRODUCT(('Project Inputs'!$A$6:$A$11=A5)*'Project Inputs'!$E$6:$E$11/IF('Project Inputs'!$G$6:$G$11=0,1,'Project Inputs'!$G$6:$G$11)) -> #VALUE! | C5: =IFERROR(SUMPRODUCT(('Baseline Inputs'!$A$6:$A$15=A5)*'Baseline Inputs'!$E$6:$E$15/IF('Baseline Inputs'!$G$6:$G$15=0,1,'Baseline Inputs'!$G$6:$G$15))/MAX(1,COUNTIF('Baseline Inputs'!$A$6:$A$15,A5)),0) -> 0 | D5: =MAX(0,B5-C5) -> #VALUE! | E5: 0.3 | F5: no | G5: =IF(F5="yes",0,D5*E5*0.12*(44/12)) -> #VALUE! | H5: C-content: compost ~0.30, cattle manure ~0.15 t C/t — confirm by analysis. Exempt if produced on-site / from uncontrolled anaerobic storage / not a soil amendment.
A6: Farm_B | B6: =SUMPRODUCT(('Project Inputs'!$A$6:$A$11=A6)*'Project Inputs'!$E$6:$E$11/IF('Project Inputs'!$G$6:$G$11=0,1,'Project Inputs'!$G$6:$G$11)) -> #DIV/0! | C6: =IFERROR(SUMPRODUCT(('Baseline Inputs'!$A$6:$A$15=A6)*'Baseline Inputs'!$E$6:$E$15/IF('Baseline Inputs'!$G$6:$G$15=0,1,'Baseline Inputs'!$G$6:$G$15))/MAX(1,COUNTIF('Baseline Inputs'!$A$6:$A$15,A6)),0) -> 0 | D6: =MAX(0,B6-C6) -> #DIV/0! | E6: 0.3 | F6: no | G6: =IF(F6="yes",0,D6*E6*0.12*(44/12)) -> #DIV/0! | H6: C-content: compost ~0.30, cattle manure ~0.15 t C/t — confirm by analysis. Exempt if produced on-site / from uncontrolled anaerobic storage / not a soil amendment.
A7: Σ 8.4.1 | G7: =SUM(G5:G6) -> #VALUE!
A9: Other leakage components — enter t CO2e/yr with justification (default 0)
A10: Component | G10: Leakage (t CO2e) | H10: Allocated to / justification
A11: 8.4.2 · Livestock displacement (VMD0054, eq 36) | G11: 0 | H11: Reductions. 0 if no livestock displaced (document).
A12: 8.4.3 · Production declines (foregone production) | G12: 0 | H12: Reductions. Assess if yield drops vs baseline; net land conversion only.
A13: 8.4.4 · Diversion of biomass residues from energy (CDM TOOL16) | G13: 0 | H13: Reductions. 0 unless residues had a baseline energy use.
A15: Totals (allocated per eq 39 / eq 42)
A16: Leakage allocated to REDUCTIONS | G16: =G11+G12+G13 -> 0 | H16: Livestock + production declines + biomass diversion.
A17: Leakage allocated to REMOVALS | G17: =G7 -> #VALUE! | H17: Organic-amendment leakage (eq 33) — offsets SOC removals.

Sheet Project Summary (VVB)
A1: Project Summary — VVB Audit
A2: Project-wide roll-up. Reporting period = the project monitoring year entered in Project Inputs.
B4: Project identity
B5: Project name | C5: «enter»
B6: Methodology | C6: VM0042 v2.2 (Quantification Approach 3)
B7: Reporting period | C7: «enter»
B9: Activity & emissions
B10: Number of quantification units (farms) | C10: =COUNTA('Net Reductions'!A4:A5) -> 2 | D10: units | E10: From Net Reductions.
B11: Total project area | C11: ='Net Reductions'!B6 -> 80 | D11: ha
B12: Baseline emissions (project area, annual) | C12: =SUMPRODUCT('Net Reductions'!C4:C5,'Net Reductions'!B4:B5) -> 200.77315 | D12: t CO2e/yr | E12: Σ baseline t CO2e/ha × area.
B13: Project emissions (annual) | C13: =SUMPRODUCT('Net Reductions'!D4:D5,'Net Reductions'!B4:B5) -> 154.35231 | D13: t CO2e/yr
B15: Net reductions (hybrid: QA3 sources + QA1 soil N₂O)
B16: QA3 reductions (fuel, burning, +N₂O if QA3) | C16: ='Net Reductions'!F6 -> 46.420835 | D16: t CO2e/yr | E16: Σ (baseline − project). Soil N₂O auto-excluded here when approach = QA1.
B17: QA1 modeled soil-N₂O reductions | C17: ='SOC Removals (QA1)'!I13 -> 0 | D17: t CO2e/yr | E17: Nonzero only when N₂O approach = QA1 (from the QA1 sheet).
B18: Leakage allocated to reductions | C18: =Leakage!$G$16 -> 0 | D18: t CO2e/yr | E18: From Leakage sheet (§8.4.2 / 8.4.3 / 8.4.4).
